Watching for file changes with StatReloader
/home/jahongir/Desktop/culinary/users/models.py changed, reloading.
Watching for file changes with StatReloader
/home/jahongir/Desktop/culinary/recipes/views.py changed, reloading.
Watching for file changes with StatReloader
/home/jahongir/Desktop/culinary/recipes/views.py changed, reloading.
Watching for file changes with StatReloader
Watching for file changes with StatReloader
/home/jahongir/Desktop/culinary/recipes/views.py changed, reloading.
Watching for file changes with StatReloader
/home/jahongir/Desktop/culinary/recipes/views.py changed, reloading.
Watching for file changes with StatReloader
/home/jahongir/Desktop/culinary/recipes/views.py changed, reloading.
Watching for file changes with StatReloader
Watching for file changes with StatReloader
Watching for file changes with StatReloader
Watching for file changes with StatReloader
Not Found: /
[33mHTTP GET / 404 [0.03, 127.0.0.1:33750][0m
Not Found: /favicon.ico
[33mHTTP GET /favicon.ico 404 [0.02, 127.0.0.1:33750][0m
Watching for file changes with StatReloader
Not Found: /
[33mHTTP GET / 404 [0.02, 127.0.0.1:58662][0m
Not Found: /favicon.ico
[33mHTTP GET /favicon.ico 404 [0.01, 127.0.0.1:58662][0m
Not Found: /
[33mHTTP GET / 404 [0.01, 127.0.0.1:58662][0m
Not Found: /
[33mHTTP GET / 404 [0.01, 127.0.0.1:58662][0m
Not Found: /
[33mHTTP GET / 404 [0.01, 127.0.0.1:58662][0m
Not Found: /
[33mHTTP GET / 404 [0.01, 127.0.0.1:58662][0m
/home/jahongir/Desktop/culinary/core/urls.py changed, reloading.
Watching for file changes with StatReloader
[mHTTP GET / 200 [0.01, 127.0.0.1:50636][0m
Not Found: /favicon.ico
[33mHTTP GET /favicon.ico 404 [0.01, 127.0.0.1:50636][0m
[mHTTP GET / 200 [0.00, 127.0.0.1:50636][0m
Not Found: /api/swagger/
[33mHTTP GET /api/swagger/ 404 [0.01, 127.0.0.1:50636][0m
Not Found: /api/swagger/
[33mHTTP GET /api/swagger/ 404 [0.01, 127.0.0.1:50636][0m
Not Found: /swagger/
[33mHTTP GET /swagger/ 404 [0.01, 127.0.0.1:50636][0m
Not Found: /swagger/
[33mHTTP GET /swagger/ 404 [0.01, 127.0.0.1:50636][0m
/home/jahongir/Desktop/culinary/core/urls.py changed, reloading.
Watching for file changes with StatReloader
[mHTTP GET / 200 [0.02, 127.0.0.1:34462][0m
[mHTTP GET /swagger/ 200 [0.03, 127.0.0.1:34462][0m
Internal Server Error: /api/schema/
Traceback (most recent call last):
  File "/home/jahongir/Desktop/culinary/.venv/lib/python3.13/site-packages/asgiref/sync.py", line 489, in thread_handler
    raise exc_info[1]
  File "/home/jahongir/Desktop/culinary/.venv/lib/python3.13/site-packages/django/core/handlers/exception.py", line 42, in inner
    response = await get_response(request)
               ^^^^^^^^^^^^^^^^^^^^^^^^^^^
  File "/home/jahongir/Desktop/culinary/.venv/lib/python3.13/site-packages/asgiref/sync.py", line 489, in thread_handler
    raise exc_info[1]
  File "/home/jahongir/Desktop/culinary/.venv/lib/python3.13/site-packages/django/core/handlers/base.py", line 253, in _get_response_async
    response = await wrapped_callback(
               ^^^^^^^^^^^^^^^^^^^^^^^
        request, *callback_args, **callback_kwargs
        ^^^^^^^^^^^^^^^^^^^^^^^^^^^^^^^^^^^^^^^^^^
    )
    ^
  File "/home/jahongir/Desktop/culinary/.venv/lib/python3.13/site-packages/asgiref/sync.py", line 439, in __call__
    ret = await asyncio.shield(exec_coro)
          ^^^^^^^^^^^^^^^^^^^^^^^^^^^^^^^
  File "/home/jahongir/.local/share/uv/python/cpython-3.13.5-linux-x86_64-gnu/lib/python3.13/concurrent/futures/thread.py", line 59, in run
    result = self.fn(*self.args, **self.kwargs)
  File "/home/jahongir/Desktop/culinary/.venv/lib/python3.13/site-packages/asgiref/sync.py", line 493, in thread_handler
    return func(*args, **kwargs)
  File "/home/jahongir/Desktop/culinary/.venv/lib/python3.13/site-packages/django/views/decorators/csrf.py", line 65, in _view_wrapper
    return view_func(request, *args, **kwargs)
  File "/home/jahongir/Desktop/culinary/.venv/lib/python3.13/site-packages/django/views/generic/base.py", line 105, in view
    return self.dispatch(request, *args, **kwargs)
           ~~~~~~~~~~~~~^^^^^^^^^^^^^^^^^^^^^^^^^^
  File "/home/jahongir/Desktop/culinary/.venv/lib/python3.13/site-packages/rest_framework/views.py", line 515, in dispatch
    response = self.handle_exception(exc)
  File "/home/jahongir/Desktop/culinary/.venv/lib/python3.13/site-packages/rest_framework/views.py", line 475, in handle_exception
    self.raise_uncaught_exception(exc)
    ~~~~~~~~~~~~~~~~~~~~~~~~~~~~~^^^^^
  File "/home/jahongir/Desktop/culinary/.venv/lib/python3.13/site-packages/rest_framework/views.py", line 486, in raise_uncaught_exception
    raise exc
  File "/home/jahongir/Desktop/culinary/.venv/lib/python3.13/site-packages/rest_framework/views.py", line 512, in dispatch
    response = handler(request, *args, **kwargs)
  File "/home/jahongir/Desktop/culinary/.venv/lib/python3.13/site-packages/drf_spectacular/views.py", line 84, in get
    return self._get_schema_response(request)
           ~~~~~~~~~~~~~~~~~~~~~~~~~^^^^^^^^^
  File "/home/jahongir/Desktop/culinary/.venv/lib/python3.13/site-packages/drf_spectacular/views.py", line 92, in _get_schema_response
    data=generator.get_schema(request=request, public=self.serve_public),
         ~~~~~~~~~~~~~~~~~~~~^^^^^^^^^^^^^^^^^^^^^^^^^^^^^^^^^^^^^^^^^^^
  File "/home/jahongir/Desktop/culinary/.venv/lib/python3.13/site-packages/drf_spectacular/generators.py", line 285, in get_schema
    paths=self.parse(request, public),
          ~~~~~~~~~~^^^^^^^^^^^^^^^^^
  File "/home/jahongir/Desktop/culinary/.venv/lib/python3.13/site-packages/drf_spectacular/generators.py", line 256, in parse
    operation = view.schema.get_operation(
        path, path_regex, path_prefix, method, self.registry
    )
  File "/home/jahongir/Desktop/culinary/.venv/lib/python3.13/site-packages/drf_spectacular/openapi.py", line 112, in get_operation
    operation['responses'] = self._get_response_bodies()
                             ~~~~~~~~~~~~~~~~~~~~~~~~~^^
  File "/home/jahongir/Desktop/culinary/.venv/lib/python3.13/site-packages/drf_spectacular/openapi.py", line 1397, in _get_response_bodies
    return {'200': self._get_response_for_code(response_serializers, '200', direction=direction)}
                   ~~~~~~~~~~~~~~~~~~~~~~~~~~~^^^^^^^^^^^^^^^^^^^^^^^^^^^^^^^^^^^^^^^^^^^^^^^^^^
  File "/home/jahongir/Desktop/culinary/.venv/lib/python3.13/site-packages/drf_spectacular/openapi.py", line 1453, in _get_response_for_code
    component = self.resolve_serializer(serializer, direction)
  File "/home/jahongir/Desktop/culinary/.venv/lib/python3.13/site-packages/drf_spectacular/openapi.py", line 1648, in resolve_serializer
    component.schema = self._map_serializer(serializer, direction, bypass_extensions)
                       ~~~~~~~~~~~~~~~~~~~~^^^^^^^^^^^^^^^^^^^^^^^^^^^^^^^^^^^^^^^^^^
  File "/home/jahongir/Desktop/culinary/.venv/lib/python3.13/site-packages/drf_spectacular/openapi.py", line 949, in _map_serializer
    schema = self._map_basic_serializer(serializer, direction)
  File "/home/jahongir/Desktop/culinary/.venv/lib/python3.13/site-packages/drf_spectacular/openapi.py", line 1042, in _map_basic_serializer
    for field in serializer.fields.values():
                 ^^^^^^^^^^^^^^^^^
  File "/home/jahongir/Desktop/culinary/.venv/lib/python3.13/site-packages/django/utils/functional.py", line 47, in __get__
    res = instance.__dict__[self.name] = self.func(instance)
                                         ~~~~~~~~~^^^^^^^^^^
  File "/home/jahongir/Desktop/culinary/.venv/lib/python3.13/site-packages/rest_framework/serializers.py", line 374, in fields
    for key, value in self.get_fields().items():
                      ~~~~~~~~~~~~~~~^^
  File "/home/jahongir/Desktop/culinary/.venv/lib/python3.13/site-packages/rest_framework/serializers.py", line 1105, in get_fields
    field_class, field_kwargs = self.build_field(
                                ~~~~~~~~~~~~~~~~^
        source, info, model, depth
        ^^^^^^^^^^^^^^^^^^^^^^^^^^
    )
    ^
  File "/home/jahongir/Desktop/culinary/.venv/lib/python3.13/site-packages/rest_framework/serializers.py", line 1251, in build_field
    return self.build_unknown_field(field_name, model_class)
           ~~~~~~~~~~~~~~~~~~~~~~~~^^^^^^^^^^^^^^^^^^^^^^^^^
  File "/home/jahongir/Desktop/culinary/.venv/lib/python3.13/site-packages/rest_framework/serializers.py", line 1369, in build_unknown_field
    raise ImproperlyConfigured(
    ...<2 lines>...
    )
django.core.exceptions.ImproperlyConfigured: Field name `score` is not valid for model `Rating` in `recipes.serializers.RatingSerializer`.
[35;1mHTTP GET /api/schema/ 500 [0.12, 127.0.0.1:34462][0m
Internal Server Error: /api/schema/
Traceback (most recent call last):
  File "/home/jahongir/Desktop/culinary/.venv/lib/python3.13/site-packages/asgiref/sync.py", line 489, in thread_handler
    raise exc_info[1]
  File "/home/jahongir/Desktop/culinary/.venv/lib/python3.13/site-packages/django/core/handlers/exception.py", line 42, in inner
    response = await get_response(request)
               ^^^^^^^^^^^^^^^^^^^^^^^^^^^
  File "/home/jahongir/Desktop/culinary/.venv/lib/python3.13/site-packages/asgiref/sync.py", line 489, in thread_handler
    raise exc_info[1]
  File "/home/jahongir/Desktop/culinary/.venv/lib/python3.13/site-packages/django/core/handlers/base.py", line 253, in _get_response_async
    response = await wrapped_callback(
               ^^^^^^^^^^^^^^^^^^^^^^^
        request, *callback_args, **callback_kwargs
        ^^^^^^^^^^^^^^^^^^^^^^^^^^^^^^^^^^^^^^^^^^
    )
    ^
  File "/home/jahongir/Desktop/culinary/.venv/lib/python3.13/site-packages/asgiref/sync.py", line 439, in __call__
    ret = await asyncio.shield(exec_coro)
          ^^^^^^^^^^^^^^^^^^^^^^^^^^^^^^^
  File "/home/jahongir/.local/share/uv/python/cpython-3.13.5-linux-x86_64-gnu/lib/python3.13/concurrent/futures/thread.py", line 59, in run
    result = self.fn(*self.args, **self.kwargs)
  File "/home/jahongir/Desktop/culinary/.venv/lib/python3.13/site-packages/asgiref/sync.py", line 493, in thread_handler
    return func(*args, **kwargs)
  File "/home/jahongir/Desktop/culinary/.venv/lib/python3.13/site-packages/django/views/decorators/csrf.py", line 65, in _view_wrapper
    return view_func(request, *args, **kwargs)
  File "/home/jahongir/Desktop/culinary/.venv/lib/python3.13/site-packages/django/views/generic/base.py", line 105, in view
    return self.dispatch(request, *args, **kwargs)
           ~~~~~~~~~~~~~^^^^^^^^^^^^^^^^^^^^^^^^^^
  File "/home/jahongir/Desktop/culinary/.venv/lib/python3.13/site-packages/rest_framework/views.py", line 515, in dispatch
    response = self.handle_exception(exc)
  File "/home/jahongir/Desktop/culinary/.venv/lib/python3.13/site-packages/rest_framework/views.py", line 475, in handle_exception
    self.raise_uncaught_exception(exc)
    ~~~~~~~~~~~~~~~~~~~~~~~~~~~~~^^^^^
  File "/home/jahongir/Desktop/culinary/.venv/lib/python3.13/site-packages/rest_framework/views.py", line 486, in raise_uncaught_exception
    raise exc
  File "/home/jahongir/Desktop/culinary/.venv/lib/python3.13/site-packages/rest_framework/views.py", line 512, in dispatch
    response = handler(request, *args, **kwargs)
  File "/home/jahongir/Desktop/culinary/.venv/lib/python3.13/site-packages/drf_spectacular/views.py", line 84, in get
    return self._get_schema_response(request)
           ~~~~~~~~~~~~~~~~~~~~~~~~~^^^^^^^^^
  File "/home/jahongir/Desktop/culinary/.venv/lib/python3.13/site-packages/drf_spectacular/views.py", line 92, in _get_schema_response
    data=generator.get_schema(request=request, public=self.serve_public),
         ~~~~~~~~~~~~~~~~~~~~^^^^^^^^^^^^^^^^^^^^^^^^^^^^^^^^^^^^^^^^^^^
  File "/home/jahongir/Desktop/culinary/.venv/lib/python3.13/site-packages/drf_spectacular/generators.py", line 285, in get_schema
    paths=self.parse(request, public),
          ~~~~~~~~~~^^^^^^^^^^^^^^^^^
  File "/home/jahongir/Desktop/culinary/.venv/lib/python3.13/site-packages/drf_spectacular/generators.py", line 256, in parse
    operation = view.schema.get_operation(
        path, path_regex, path_prefix, method, self.registry
    )
  File "/home/jahongir/Desktop/culinary/.venv/lib/python3.13/site-packages/drf_spectacular/openapi.py", line 112, in get_operation
    operation['responses'] = self._get_response_bodies()
                             ~~~~~~~~~~~~~~~~~~~~~~~~~^^
  File "/home/jahongir/Desktop/culinary/.venv/lib/python3.13/site-packages/drf_spectacular/openapi.py", line 1397, in _get_response_bodies
    return {'200': self._get_response_for_code(response_serializers, '200', direction=direction)}
                   ~~~~~~~~~~~~~~~~~~~~~~~~~~~^^^^^^^^^^^^^^^^^^^^^^^^^^^^^^^^^^^^^^^^^^^^^^^^^^
  File "/home/jahongir/Desktop/culinary/.venv/lib/python3.13/site-packages/drf_spectacular/openapi.py", line 1453, in _get_response_for_code
    component = self.resolve_serializer(serializer, direction)
  File "/home/jahongir/Desktop/culinary/.venv/lib/python3.13/site-packages/drf_spectacular/openapi.py", line 1648, in resolve_serializer
    component.schema = self._map_serializer(serializer, direction, bypass_extensions)
                       ~~~~~~~~~~~~~~~~~~~~^^^^^^^^^^^^^^^^^^^^^^^^^^^^^^^^^^^^^^^^^^
  File "/home/jahongir/Desktop/culinary/.venv/lib/python3.13/site-packages/drf_spectacular/openapi.py", line 949, in _map_serializer
    schema = self._map_basic_serializer(serializer, direction)
  File "/home/jahongir/Desktop/culinary/.venv/lib/python3.13/site-packages/drf_spectacular/openapi.py", line 1042, in _map_basic_serializer
    for field in serializer.fields.values():
                 ^^^^^^^^^^^^^^^^^
  File "/home/jahongir/Desktop/culinary/.venv/lib/python3.13/site-packages/django/utils/functional.py", line 47, in __get__
    res = instance.__dict__[self.name] = self.func(instance)
                                         ~~~~~~~~~^^^^^^^^^^
  File "/home/jahongir/Desktop/culinary/.venv/lib/python3.13/site-packages/rest_framework/serializers.py", line 374, in fields
    for key, value in self.get_fields().items():
                      ~~~~~~~~~~~~~~~^^
  File "/home/jahongir/Desktop/culinary/.venv/lib/python3.13/site-packages/rest_framework/serializers.py", line 1105, in get_fields
    field_class, field_kwargs = self.build_field(
                                ~~~~~~~~~~~~~~~~^
        source, info, model, depth
        ^^^^^^^^^^^^^^^^^^^^^^^^^^
    )
    ^
  File "/home/jahongir/Desktop/culinary/.venv/lib/python3.13/site-packages/rest_framework/serializers.py", line 1251, in build_field
    return self.build_unknown_field(field_name, model_class)
           ~~~~~~~~~~~~~~~~~~~~~~~~^^^^^^^^^^^^^^^^^^^^^^^^^
  File "/home/jahongir/Desktop/culinary/.venv/lib/python3.13/site-packages/rest_framework/serializers.py", line 1369, in build_unknown_field
    raise ImproperlyConfigured(
    ...<2 lines>...
    )
django.core.exceptions.ImproperlyConfigured: Field name `score` is not valid for model `Rating` in `recipes.serializers.RatingSerializer`.
[35;1mHTTP GET /api/schema/ 500 [0.09, 127.0.0.1:34462][0m
/home/jahongir/Desktop/culinary/recipes/models.py changed, reloading.
Watching for file changes with StatReloader
[mHTTP GET / 200 [0.01, 127.0.0.1:52528][0m
[mHTTP GET /swagger/ 200 [0.02, 127.0.0.1:52528][0m
[mHTTP GET /api/schema/ 200 [0.06, 127.0.0.1:52528][0m
Watching for file changes with StatReloader
[mHTTP GET / 200 [0.01, 127.0.0.1:39170][0m
[32mHTTP GET /admin/ 302 [0.03, 127.0.0.1:39170][0m
[mHTTP GET /admin/login/?next=/admin/ 200 [0.02, 127.0.0.1:39170][0m
[36mHTTP GET /static/vendor/fontawesome-free/css/all.min.css 304 [0.01, 127.0.0.1:39170][0m
[36mHTTP GET /static/vendor/adminlte/css/adminlte.min.css 304 [0.01, 127.0.0.1:39180][0m
[36mHTTP GET /static/jazzmin/css/main.css 304 [0.01, 127.0.0.1:59252][0m
[36mHTTP GET /static/vendor/bootstrap/js/bootstrap.min.js 304 [0.00, 127.0.0.1:39170][0m
[mHTTP GET /static/vendor/adminlte/img/AdminLTELogo.png 200 [0.01, 127.0.0.1:59252][0m
[mHTTP GET /static/admin/js/vendor/jquery/jquery.js 200 [0.02, 127.0.0.1:39180][0m
[36mHTTP GET /static/vendor/adminlte/js/adminlte.min.js 304 [0.00, 127.0.0.1:39180][0m
[36mHTTP GET /static/vendor/fontawesome-free/webfonts/fa-solid-900.woff2 304 [0.00, 127.0.0.1:39180][0m
[32mHTTP POST /admin/login/?next=/admin/ 302 [0.40, 127.0.0.1:39180][0m
[mHTTP GET /admin/ 200 [0.05, 127.0.0.1:39180][0m
[36mHTTP GET /static/jazzmin/js/main.js 304 [0.00, 127.0.0.1:39180][0m
[36mHTTP GET /static/vendor/fontawesome-free/webfonts/fa-regular-400.woff2 304 [0.00, 127.0.0.1:39180][0m
[32mHTTP GET /admin/login/?next=/admin/ 302 [0.02, 127.0.0.1:39180][0m
[mHTTP GET /admin/ 200 [0.03, 127.0.0.1:39180][0m
[mHTTP GET /admin/ 200 [0.04, 127.0.0.1:39180][0m
Watching for file changes with StatReloader
[mHTTP GET / 200 [0.01, 127.0.0.1:56118][0m
[mHTTP GET / 200 [0.01, 127.0.0.1:56118][0m
[mHTTP GET /admin/ 200 [0.07, 127.0.0.1:56118][0m
[mHTTP GET /admin/ 200 [0.05, 127.0.0.1:56118][0m
[mHTTP GET /admin/ 200 [0.04, 127.0.0.1:56118][0m
[mHTTP GET /admin/ 200 [0.04, 127.0.0.1:56118][0m
[mHTTP GET /admin/ 200 [0.04, 127.0.0.1:56118][0m
[mHTTP GET /admin/ 200 [0.04, 127.0.0.1:56118][0m
[mHTTP GET /admin/auth/group/ 200 [0.06, 127.0.0.1:56118][0m
[36mHTTP GET /static/vendor/select2/css/select2.min.css 304 [0.00, 127.0.0.1:56118][0m
[mHTTP GET /static/admin/js/jquery.init.js 200 [0.02, 127.0.0.1:56134][0m
[mHTTP GET /static/admin/js/actions.js 200 [0.03, 127.0.0.1:58052][0m
[mHTTP GET /static/admin/js/admin/RelatedObjectLookups.js 200 [0.03, 127.0.0.1:58040][0m
[mHTTP GET /static/admin/js/core.js 200 [0.03, 127.0.0.1:58026][0m
[mHTTP GET /static/admin/js/urlify.js 200 [0.03, 127.0.0.1:58058][0m
[mHTTP GET /static/admin/js/prepopulate.js 200 [0.01, 127.0.0.1:56134][0m
[36mHTTP GET /static/vendor/select2/js/select2.min.js 304 [0.00, 127.0.0.1:58058][0m
[36mHTTP GET /static/jazzmin/js/change_list.js 304 [0.00, 127.0.0.1:56134][0m
[mHTTP GET /static/admin/js/vendor/xregexp/xregexp.js 200 [0.01, 127.0.0.1:58026][0m
[mHTTP GET /admin/jsi18n/ 200 [0.06, 127.0.0.1:56118][0m
[mHTTP GET /admin/auth/group/ 200 [0.03, 127.0.0.1:56118][0m
[mHTTP GET /admin/jsi18n/ 200 [0.02, 127.0.0.1:56118][0m
[mHTTP GET /admin/auth/group/?q= 200 [0.04, 127.0.0.1:56118][0m
[mHTTP GET /admin/jsi18n/ 200 [0.03, 127.0.0.1:56118][0m
[mHTTP GET /admin/auth/group/ 200 [0.05, 127.0.0.1:56118][0m
Watching for file changes with StatReloader
[mHTTP GET / 200 [0.03, 127.0.0.1:38332][0m
Not Found: /favicon.ico
[33mHTTP GET /favicon.ico 404 [0.01, 127.0.0.1:38360][0m
[mHTTP GET /admin/ 200 [0.06, 127.0.0.1:38372][0m
[mHTTP GET /admin/ 200 [0.04, 127.0.0.1:38372][0m
Watching for file changes with StatReloader
[mHTTP GET /swagger/ 200 [0.03, 127.0.0.1:50732][0m
[mHTTP GET /api/schema/ 200 [0.06, 127.0.0.1:50732][0m
[mHTTP POST /api/token/ 200 [0.40, 127.0.0.1:50732][0m
Internal Server Error: /recipes/categories/
Traceback (most recent call last):
  File "/home/jahongir/Desktop/culinary/.venv/lib/python3.13/site-packages/django/db/backends/utils.py", line 105, in _execute
    return self.cursor.execute(sql, params)
           ~~~~~~~~~~~~~~~~~~~^^^^^^^^^^^^^
psycopg2.errors.UndefinedTable: relation "recipes_category" does not exist
LINE 1: ...gory"."slug", "recipes_category"."is_active" FROM "recipes_c...
                                                             ^


The above exception was the direct cause of the following exception:

Traceback (most recent call last):
  File "/home/jahongir/Desktop/culinary/.venv/lib/python3.13/site-packages/asgiref/sync.py", line 489, in thread_handler
    raise exc_info[1]
  File "/home/jahongir/Desktop/culinary/.venv/lib/python3.13/site-packages/django/core/handlers/exception.py", line 42, in inner
    response = await get_response(request)
               ^^^^^^^^^^^^^^^^^^^^^^^^^^^
  File "/home/jahongir/Desktop/culinary/.venv/lib/python3.13/site-packages/asgiref/sync.py", line 489, in thread_handler
    raise exc_info[1]
  File "/home/jahongir/Desktop/culinary/.venv/lib/python3.13/site-packages/django/core/handlers/base.py", line 253, in _get_response_async
    response = await wrapped_callback(
               ^^^^^^^^^^^^^^^^^^^^^^^
        request, *callback_args, **callback_kwargs
        ^^^^^^^^^^^^^^^^^^^^^^^^^^^^^^^^^^^^^^^^^^
    )
    ^
  File "/home/jahongir/Desktop/culinary/.venv/lib/python3.13/site-packages/asgiref/sync.py", line 439, in __call__
    ret = await asyncio.shield(exec_coro)
          ^^^^^^^^^^^^^^^^^^^^^^^^^^^^^^^
  File "/home/jahongir/.local/share/uv/python/cpython-3.13.5-linux-x86_64-gnu/lib/python3.13/concurrent/futures/thread.py", line 59, in run
    result = self.fn(*self.args, **self.kwargs)
  File "/home/jahongir/Desktop/culinary/.venv/lib/python3.13/site-packages/asgiref/sync.py", line 493, in thread_handler
    return func(*args, **kwargs)
  File "/home/jahongir/Desktop/culinary/.venv/lib/python3.13/site-packages/django/views/decorators/csrf.py", line 65, in _view_wrapper
    return view_func(request, *args, **kwargs)
  File "/home/jahongir/Desktop/culinary/.venv/lib/python3.13/site-packages/django/views/generic/base.py", line 105, in view
    return self.dispatch(request, *args, **kwargs)
           ~~~~~~~~~~~~~^^^^^^^^^^^^^^^^^^^^^^^^^^
  File "/home/jahongir/Desktop/culinary/.venv/lib/python3.13/site-packages/rest_framework/views.py", line 515, in dispatch
    response = self.handle_exception(exc)
  File "/home/jahongir/Desktop/culinary/.venv/lib/python3.13/site-packages/rest_framework/views.py", line 475, in handle_exception
    self.raise_uncaught_exception(exc)
    ~~~~~~~~~~~~~~~~~~~~~~~~~~~~~^^^^^
  File "/home/jahongir/Desktop/culinary/.venv/lib/python3.13/site-packages/rest_framework/views.py", line 486, in raise_uncaught_exception
    raise exc
  File "/home/jahongir/Desktop/culinary/.venv/lib/python3.13/site-packages/rest_framework/views.py", line 512, in dispatch
    response = handler(request, *args, **kwargs)
  File "/home/jahongir/Desktop/culinary/.venv/lib/python3.13/site-packages/rest_framework/generics.py", line 203, in get
    return self.list(request, *args, **kwargs)
           ~~~~~~~~~^^^^^^^^^^^^^^^^^^^^^^^^^^
  File "/home/jahongir/Desktop/culinary/.venv/lib/python3.13/site-packages/rest_framework/mixins.py", line 46, in list
    return Response(serializer.data)
                    ^^^^^^^^^^^^^^^
  File "/home/jahongir/Desktop/culinary/.venv/lib/python3.13/site-packages/rest_framework/serializers.py", line 797, in data
    ret = super().data
          ^^^^^^^^^^^^
  File "/home/jahongir/Desktop/culinary/.venv/lib/python3.13/site-packages/rest_framework/serializers.py", line 251, in data
    self._data = self.to_representation(self.instance)
                 ~~~~~~~~~~~~~~~~~~~~~~^^^^^^^^^^^^^^^
  File "/home/jahongir/Desktop/culinary/.venv/lib/python3.13/site-packages/rest_framework/serializers.py", line 716, in to_representation
    self.child.to_representation(item) for item in iterable
                                                   ^^^^^^^^
  File "/home/jahongir/Desktop/culinary/.venv/lib/python3.13/site-packages/django/db/models/query.py", line 384, in __iter__
    self._fetch_all()
    ~~~~~~~~~~~~~~~^^
  File "/home/jahongir/Desktop/culinary/.venv/lib/python3.13/site-packages/django/db/models/query.py", line 1949, in _fetch_all
    self._result_cache = list(self._iterable_class(self))
                         ~~~~^^^^^^^^^^^^^^^^^^^^^^^^^^^^
  File "/home/jahongir/Desktop/culinary/.venv/lib/python3.13/site-packages/django/db/models/query.py", line 91, in __iter__
    results = compiler.execute_sql(
        chunked_fetch=self.chunked_fetch, chunk_size=self.chunk_size
    )
  File "/home/jahongir/Desktop/culinary/.venv/lib/python3.13/site-packages/django/db/models/sql/compiler.py", line 1623, in execute_sql
    cursor.execute(sql, params)
    ~~~~~~~~~~~~~~^^^^^^^^^^^^^
  File "/home/jahongir/Desktop/culinary/.venv/lib/python3.13/site-packages/django/db/backends/utils.py", line 122, in execute
    return super().execute(sql, params)
           ~~~~~~~~~~~~~~~^^^^^^^^^^^^^
  File "/home/jahongir/Desktop/culinary/.venv/lib/python3.13/site-packages/django/db/backends/utils.py", line 79, in execute
    return self._execute_with_wrappers(
           ~~~~~~~~~~~~~~~~~~~~~~~~~~~^
        sql, params, many=False, executor=self._execute
        ^^^^^^^^^^^^^^^^^^^^^^^^^^^^^^^^^^^^^^^^^^^^^^^
    )
    ^
  File "/home/jahongir/Desktop/culinary/.venv/lib/python3.13/site-packages/django/db/backends/utils.py", line 92, in _execute_with_wrappers
    return executor(sql, params, many, context)
  File "/home/jahongir/Desktop/culinary/.venv/lib/python3.13/site-packages/django/db/backends/utils.py", line 100, in _execute
    with self.db.wrap_database_errors:
         ^^^^^^^^^^^^^^^^^^^^^^^^^^^^
  File "/home/jahongir/Desktop/culinary/.venv/lib/python3.13/site-packages/django/db/utils.py", line 91, in __exit__
    raise dj_exc_value.with_traceback(traceback) from exc_value
  File "/home/jahongir/Desktop/culinary/.venv/lib/python3.13/site-packages/django/db/backends/utils.py", line 105, in _execute
    return self.cursor.execute(sql, params)
           ~~~~~~~~~~~~~~~~~~~^^^^^^^^^^^^^
django.db.utils.ProgrammingError: relation "recipes_category" does not exist
LINE 1: ...gory"."slug", "recipes_category"."is_active" FROM "recipes_c...
                                                             ^

[35;1mHTTP GET /recipes/categories/ 500 [0.08, 127.0.0.1:50732][0m
Internal Server Error: /recipes/categories/create/
Traceback (most recent call last):
  File "/home/jahongir/Desktop/culinary/.venv/lib/python3.13/site-packages/django/db/backends/utils.py", line 105, in _execute
    return self.cursor.execute(sql, params)
           ~~~~~~~~~~~~~~~~~~~^^^^^^^^^^^^^
psycopg2.errors.UndefinedTable: relation "recipes_category" does not exist
LINE 1: SELECT 1 AS "a" FROM "recipes_category" WHERE "recipes_categ...
                             ^


The above exception was the direct cause of the following exception:

Traceback (most recent call last):
  File "/home/jahongir/Desktop/culinary/.venv/lib/python3.13/site-packages/asgiref/sync.py", line 489, in thread_handler
    raise exc_info[1]
  File "/home/jahongir/Desktop/culinary/.venv/lib/python3.13/site-packages/django/core/handlers/exception.py", line 42, in inner
    response = await get_response(request)
               ^^^^^^^^^^^^^^^^^^^^^^^^^^^
  File "/home/jahongir/Desktop/culinary/.venv/lib/python3.13/site-packages/asgiref/sync.py", line 489, in thread_handler
    raise exc_info[1]
  File "/home/jahongir/Desktop/culinary/.venv/lib/python3.13/site-packages/django/core/handlers/base.py", line 253, in _get_response_async
    response = await wrapped_callback(
               ^^^^^^^^^^^^^^^^^^^^^^^
        request, *callback_args, **callback_kwargs
        ^^^^^^^^^^^^^^^^^^^^^^^^^^^^^^^^^^^^^^^^^^
    )
    ^
  File "/home/jahongir/Desktop/culinary/.venv/lib/python3.13/site-packages/asgiref/sync.py", line 439, in __call__
    ret = await asyncio.shield(exec_coro)
          ^^^^^^^^^^^^^^^^^^^^^^^^^^^^^^^
  File "/home/jahongir/.local/share/uv/python/cpython-3.13.5-linux-x86_64-gnu/lib/python3.13/concurrent/futures/thread.py", line 59, in run
    result = self.fn(*self.args, **self.kwargs)
  File "/home/jahongir/Desktop/culinary/.venv/lib/python3.13/site-packages/asgiref/sync.py", line 493, in thread_handler
    return func(*args, **kwargs)
  File "/home/jahongir/Desktop/culinary/.venv/lib/python3.13/site-packages/django/views/decorators/csrf.py", line 65, in _view_wrapper
    return view_func(request, *args, **kwargs)
  File "/home/jahongir/Desktop/culinary/.venv/lib/python3.13/site-packages/django/views/generic/base.py", line 105, in view
    return self.dispatch(request, *args, **kwargs)
           ~~~~~~~~~~~~~^^^^^^^^^^^^^^^^^^^^^^^^^^
  File "/home/jahongir/Desktop/culinary/.venv/lib/python3.13/site-packages/rest_framework/views.py", line 515, in dispatch
    response = self.handle_exception(exc)
  File "/home/jahongir/Desktop/culinary/.venv/lib/python3.13/site-packages/rest_framework/views.py", line 475, in handle_exception
    self.raise_uncaught_exception(exc)
    ~~~~~~~~~~~~~~~~~~~~~~~~~~~~~^^^^^
  File "/home/jahongir/Desktop/culinary/.venv/lib/python3.13/site-packages/rest_framework/views.py", line 486, in raise_uncaught_exception
    raise exc
  File "/home/jahongir/Desktop/culinary/.venv/lib/python3.13/site-packages/rest_framework/views.py", line 512, in dispatch
    response = handler(request, *args, **kwargs)
  File "/home/jahongir/Desktop/culinary/.venv/lib/python3.13/site-packages/rest_framework/generics.py", line 194, in post
    return self.create(request, *args, **kwargs)
           ~~~~~~~~~~~^^^^^^^^^^^^^^^^^^^^^^^^^^
  File "/home/jahongir/Desktop/culinary/.venv/lib/python3.13/site-packages/rest_framework/mixins.py", line 18, in create
    serializer.is_valid(raise_exception=True)
    ~~~~~~~~~~~~~~~~~~~^^^^^^^^^^^^^^^^^^^^^^
  File "/home/jahongir/Desktop/culinary/.venv/lib/python3.13/site-packages/rest_framework/serializers.py", line 225, in is_valid
    self._validated_data = self.run_validation(self.initial_data)
                           ~~~~~~~~~~~~~~~~~~~^^^^^^^^^^^^^^^^^^^
  File "/home/jahongir/Desktop/culinary/.venv/lib/python3.13/site-packages/rest_framework/serializers.py", line 444, in run_validation
    value = self.to_internal_value(data)
  File "/home/jahongir/Desktop/culinary/.venv/lib/python3.13/site-packages/rest_framework/serializers.py", line 501, in to_internal_value
    validated_value = field.run_validation(primitive_value)
  File "/home/jahongir/Desktop/culinary/.venv/lib/python3.13/site-packages/rest_framework/fields.py", line 757, in run_validation
    return super().run_validation(data)
           ~~~~~~~~~~~~~~~~~~~~~~^^^^^^
  File "/home/jahongir/Desktop/culinary/.venv/lib/python3.13/site-packages/rest_framework/fields.py", line 539, in run_validation
    self.run_validators(value)
    ~~~~~~~~~~~~~~~~~~~^^^^^^^
  File "/home/jahongir/Desktop/culinary/.venv/lib/python3.13/site-packages/rest_framework/fields.py", line 551, in run_validators
    validator(value, self)
    ~~~~~~~~~^^^^^^^^^^^^^
  File "/home/jahongir/Desktop/culinary/.venv/lib/python3.13/site-packages/rest_framework/validators.py", line 86, in __call__
    if qs_exists(queryset):
       ~~~~~~~~~^^^^^^^^^^
  File "/home/jahongir/Desktop/culinary/.venv/lib/python3.13/site-packages/rest_framework/validators.py", line 23, in qs_exists
    return queryset.exists()
           ~~~~~~~~~~~~~~~^^
  File "/home/jahongir/Desktop/culinary/.venv/lib/python3.13/site-packages/django/db/models/query.py", line 1296, in exists
    return self.query.has_results(using=self.db)
           ~~~~~~~~~~~~~~~~~~~~~~^^^^^^^^^^^^^^^
  File "/home/jahongir/Desktop/culinary/.venv/lib/python3.13/site-packages/django/db/models/sql/query.py", line 674, in has_results
    return compiler.has_results()
           ~~~~~~~~~~~~~~~~~~~~^^
  File "/home/jahongir/Desktop/culinary/.venv/lib/python3.13/site-packages/django/db/models/sql/compiler.py", line 1591, in has_results
    return bool(self.execute_sql(SINGLE))
                ~~~~~~~~~~~~~~~~^^^^^^^^
  File "/home/jahongir/Desktop/culinary/.venv/lib/python3.13/site-packages/django/db/models/sql/compiler.py", line 1623, in execute_sql
    cursor.execute(sql, params)
    ~~~~~~~~~~~~~~^^^^^^^^^^^^^
  File "/home/jahongir/Desktop/culinary/.venv/lib/python3.13/site-packages/django/db/backends/utils.py", line 122, in execute
    return super().execute(sql, params)
           ~~~~~~~~~~~~~~~^^^^^^^^^^^^^
  File "/home/jahongir/Desktop/culinary/.venv/lib/python3.13/site-packages/django/db/backends/utils.py", line 79, in execute
    return self._execute_with_wrappers(
           ~~~~~~~~~~~~~~~~~~~~~~~~~~~^
        sql, params, many=False, executor=self._execute
        ^^^^^^^^^^^^^^^^^^^^^^^^^^^^^^^^^^^^^^^^^^^^^^^
    )
    ^
  File "/home/jahongir/Desktop/culinary/.venv/lib/python3.13/site-packages/django/db/backends/utils.py", line 92, in _execute_with_wrappers
    return executor(sql, params, many, context)
  File "/home/jahongir/Desktop/culinary/.venv/lib/python3.13/site-packages/django/db/backends/utils.py", line 100, in _execute
    with self.db.wrap_database_errors:
         ^^^^^^^^^^^^^^^^^^^^^^^^^^^^
  File "/home/jahongir/Desktop/culinary/.venv/lib/python3.13/site-packages/django/db/utils.py", line 91, in __exit__
    raise dj_exc_value.with_traceback(traceback) from exc_value
  File "/home/jahongir/Desktop/culinary/.venv/lib/python3.13/site-packages/django/db/backends/utils.py", line 105, in _execute
    return self.cursor.execute(sql, params)
           ~~~~~~~~~~~~~~~~~~~^^^^^^^^^^^^^
django.db.utils.ProgrammingError: relation "recipes_category" does not exist
LINE 1: SELECT 1 AS "a" FROM "recipes_category" WHERE "recipes_categ...
                             ^

[35;1mHTTP POST /recipes/categories/create/ 500 [0.07, 127.0.0.1:50732][0m
Watching for file changes with StatReloader
[mHTTP GET /swagger/ 200 [0.03, 127.0.0.1:41058][0m
[mHTTP GET /api/schema/ 200 [0.05, 127.0.0.1:41058][0m
Unauthorized: /recipes/categories/create/
[31;1mHTTP POST /recipes/categories/create/ 401 [0.01, 127.0.0.1:41058][0m
[mHTTP POST /api/token/ 200 [0.39, 127.0.0.1:41058][0m
Not Found: /.well-known/appspecific/com.chrome.devtools.json
[33mHTTP GET /.well-known/appspecific/com.chrome.devtools.json 404 [0.01, 127.0.0.1:41058][0m
[mHTTP GET /static/drf_spectacular_sidecar/swagger-ui-dist/swagger-ui.css.map 200 [0.01, 127.0.0.1:41058][0m
[mHTTP POST /recipes/categories/create/ 201 [0.04, 127.0.0.1:41058][0m
Internal Server Error: /users/register/
Traceback (most recent call last):
  File "/home/jahongir/Desktop/culinary/.venv/lib/python3.13/site-packages/kombu/utils/functional.py", line 32, in __call__
    return self.__value__
           ^^^^^^^^^^^^^^
AttributeError: 'ChannelPromise' object has no attribute '__value__'. Did you mean: '__call__'?

During handling of the above exception, another exception occurred:

Traceback (most recent call last):
  File "/home/jahongir/Desktop/culinary/.venv/lib/python3.13/site-packages/kombu/connection.py", line 472, in _reraise_as_library_errors
    yield
  File "/home/jahongir/Desktop/culinary/.venv/lib/python3.13/site-packages/kombu/connection.py", line 459, in _ensure_connection
    return retry_over_time(
        self._connection_factory, self.recoverable_connection_errors,
    ...<2 lines>...
        callback, timeout=timeout
    )
  File "/home/jahongir/Desktop/culinary/.venv/lib/python3.13/site-packages/kombu/utils/functional.py", line 318, in retry_over_time
    return fun(*args, **kwargs)
  File "/home/jahongir/Desktop/culinary/.venv/lib/python3.13/site-packages/kombu/connection.py", line 938, in _connection_factory
    self._connection = self._establish_connection()
                       ~~~~~~~~~~~~~~~~~~~~~~~~~~^^
  File "/home/jahongir/Desktop/culinary/.venv/lib/python3.13/site-packages/kombu/connection.py", line 860, in _establish_connection
    conn = self.transport.establish_connection()
  File "/home/jahongir/Desktop/culinary/.venv/lib/python3.13/site-packages/kombu/transport/pyamqp.py", line 203, in establish_connection
    conn.connect()
    ~~~~~~~~~~~~^^
  File "/home/jahongir/Desktop/culinary/.venv/lib/python3.13/site-packages/amqp/connection.py", line 324, in connect
    self.transport.connect()
    ~~~~~~~~~~~~~~~~~~~~~~^^
  File "/home/jahongir/Desktop/culinary/.venv/lib/python3.13/site-packages/amqp/transport.py", line 132, in connect
    self._connect(self.host, self.port, self.connect_timeout)
    ~~~~~~~~~~~~~^^^^^^^^^^^^^^^^^^^^^^^^^^^^^^^^^^^^^^^^^^^^
  File "/home/jahongir/Desktop/culinary/.venv/lib/python3.13/site-packages/amqp/transport.py", line 187, in _connect
    self.sock.connect(sa)
    ~~~~~~~~~~~~~~~~~^^^^
ConnectionRefusedError: [Errno 111] Connection refused

The above exception was the direct cause of the following exception:

Traceback (most recent call last):
  File "/home/jahongir/Desktop/culinary/.venv/lib/python3.13/site-packages/asgiref/sync.py", line 489, in thread_handler
    raise exc_info[1]
  File "/home/jahongir/Desktop/culinary/.venv/lib/python3.13/site-packages/django/core/handlers/exception.py", line 42, in inner
    response = await get_response(request)
               ^^^^^^^^^^^^^^^^^^^^^^^^^^^
  File "/home/jahongir/Desktop/culinary/.venv/lib/python3.13/site-packages/asgiref/sync.py", line 489, in thread_handler
    raise exc_info[1]
  File "/home/jahongir/Desktop/culinary/.venv/lib/python3.13/site-packages/django/core/handlers/base.py", line 253, in _get_response_async
    response = await wrapped_callback(
               ^^^^^^^^^^^^^^^^^^^^^^^
        request, *callback_args, **callback_kwargs
        ^^^^^^^^^^^^^^^^^^^^^^^^^^^^^^^^^^^^^^^^^^
    )
    ^
  File "/home/jahongir/Desktop/culinary/.venv/lib/python3.13/site-packages/asgiref/sync.py", line 439, in __call__
    ret = await asyncio.shield(exec_coro)
          ^^^^^^^^^^^^^^^^^^^^^^^^^^^^^^^
  File "/home/jahongir/.local/share/uv/python/cpython-3.13.5-linux-x86_64-gnu/lib/python3.13/concurrent/futures/thread.py", line 59, in run
    result = self.fn(*self.args, **self.kwargs)
  File "/home/jahongir/Desktop/culinary/.venv/lib/python3.13/site-packages/asgiref/sync.py", line 493, in thread_handler
    return func(*args, **kwargs)
  File "/home/jahongir/Desktop/culinary/.venv/lib/python3.13/site-packages/django/views/decorators/csrf.py", line 65, in _view_wrapper
    return view_func(request, *args, **kwargs)
  File "/home/jahongir/Desktop/culinary/.venv/lib/python3.13/site-packages/django/views/generic/base.py", line 105, in view
    return self.dispatch(request, *args, **kwargs)
           ~~~~~~~~~~~~~^^^^^^^^^^^^^^^^^^^^^^^^^^
  File "/home/jahongir/Desktop/culinary/.venv/lib/python3.13/site-packages/rest_framework/views.py", line 515, in dispatch
    response = self.handle_exception(exc)
  File "/home/jahongir/Desktop/culinary/.venv/lib/python3.13/site-packages/rest_framework/views.py", line 475, in handle_exception
    self.raise_uncaught_exception(exc)
    ~~~~~~~~~~~~~~~~~~~~~~~~~~~~~^^^^^
  File "/home/jahongir/Desktop/culinary/.venv/lib/python3.13/site-packages/rest_framework/views.py", line 486, in raise_uncaught_exception
    raise exc
  File "/home/jahongir/Desktop/culinary/.venv/lib/python3.13/site-packages/rest_framework/views.py", line 512, in dispatch
    response = handler(request, *args, **kwargs)
  File "/home/jahongir/Desktop/culinary/.venv/lib/python3.13/site-packages/rest_framework/generics.py", line 194, in post
    return self.create(request, *args, **kwargs)
           ~~~~~~~~~~~^^^^^^^^^^^^^^^^^^^^^^^^^^
  File "/home/jahongir/Desktop/culinary/.venv/lib/python3.13/site-packages/rest_framework/mixins.py", line 19, in create
    self.perform_create(serializer)
    ~~~~~~~~~~~~~~~~~~~^^^^^^^^^^^^
  File "/home/jahongir/Desktop/culinary/.venv/lib/python3.13/site-packages/rest_framework/mixins.py", line 24, in perform_create
    serializer.save()
    ~~~~~~~~~~~~~~~^^
  File "/home/jahongir/Desktop/culinary/users/serializers.py", line 24, in save
    send_register_email.delay(user_id=user.id, email=user.email)
    ~~~~~~~~~~~~~~~~~~~~~~~~~^^^^^^^^^^^^^^^^^^^^^^^^^^^^^^^^^^^
  File "/home/jahongir/Desktop/culinary/.venv/lib/python3.13/site-packages/celery/app/task.py", line 444, in delay
    return self.apply_async(args, kwargs)
           ~~~~~~~~~~~~~~~~^^^^^^^^^^^^^^
  File "/home/jahongir/Desktop/culinary/.venv/lib/python3.13/site-packages/celery/app/task.py", line 601, in apply_async
    return app.send_task(
           ~~~~~~~~~~~~~^
        self.name, args, kwargs, task_id=task_id, producer=producer,
        ^^^^^^^^^^^^^^^^^^^^^^^^^^^^^^^^^^^^^^^^^^^^^^^^^^^^^^^^^^^^
    ...<2 lines>...
        **options
        ^^^^^^^^^
    )
    ^
  File "/home/jahongir/Desktop/culinary/.venv/lib/python3.13/site-packages/celery/app/base.py", line 930, in send_task
    amqp.send_task_message(P, name, message, **options)
    ~~~~~~~~~~~~~~~~~~~~~~^^^^^^^^^^^^^^^^^^^^^^^^^^^^^
  File "/home/jahongir/Desktop/culinary/.venv/lib/python3.13/site-packages/celery/app/amqp.py", line 523, in send_task_message
    ret = producer.publish(
        body,
    ...<8 lines>...
        **properties
    )
  File "/home/jahongir/Desktop/culinary/.venv/lib/python3.13/site-packages/kombu/messaging.py", line 190, in publish
    return _publish(
        body, priority, content_type, content_encoding,
        headers, properties, routing_key, mandatory, immediate,
        exchange_name, declare, timeout, confirm_timeout, retry, retry_policy
    )
  File "/home/jahongir/Desktop/culinary/.venv/lib/python3.13/site-packages/kombu/connection.py", line 556, in _ensured
    return fun(*args, **kwargs)
  File "/home/jahongir/Desktop/culinary/.venv/lib/python3.13/site-packages/kombu/messaging.py", line 200, in _publish
    channel = self.channel
              ^^^^^^^^^^^^
  File "/home/jahongir/Desktop/culinary/.venv/lib/python3.13/site-packages/kombu/messaging.py", line 224, in _get_channel
    channel = self._channel = channel()
                              ~~~~~~~^^
  File "/home/jahongir/Desktop/culinary/.venv/lib/python3.13/site-packages/kombu/utils/functional.py", line 34, in __call__
    value = self.__value__ = self.__contract__()
                             ~~~~~~~~~~~~~~~~~^^
  File "/home/jahongir/Desktop/culinary/.venv/lib/python3.13/site-packages/kombu/messaging.py", line 240, in <lambda>
    channel = ChannelPromise(lambda: connection.default_channel)
                                     ^^^^^^^^^^^^^^^^^^^^^^^^^^
  File "/home/jahongir/Desktop/culinary/.venv/lib/python3.13/site-packages/kombu/connection.py", line 957, in default_channel
    self._ensure_connection(**conn_opts)
    ~~~~~~~~~~~~~~~~~~~~~~~^^^^^^^^^^^^^
  File "/home/jahongir/Desktop/culinary/.venv/lib/python3.13/site-packages/kombu/connection.py", line 458, in _ensure_connection
    with ctx():
         ~~~^^
  File "/home/jahongir/.local/share/uv/python/cpython-3.13.5-linux-x86_64-gnu/lib/python3.13/contextlib.py", line 162, in __exit__
    self.gen.throw(value)
    ~~~~~~~~~~~~~~^^^^^^^
  File "/home/jahongir/Desktop/culinary/.venv/lib/python3.13/site-packages/kombu/connection.py", line 476, in _reraise_as_library_errors
    raise ConnectionError(str(exc)) from exc
kombu.exceptions.OperationalError: [Errno 111] Connection refused
[35;1mHTTP POST /users/register/ 500 [1.20, 127.0.0.1:41058][0m
Watching for file changes with StatReloader
[mHTTP GET / 200 [0.01, 127.0.0.1:56252][0m
Unauthorized: /users/register/
[31;1mHTTP POST /users/register/ 401 [0.02, 127.0.0.1:56252][0m
Watching for file changes with StatReloader
[mHTTP GET / 200 [0.01, 127.0.0.1:48040][0m
[mHTTP GET /swagger/ 200 [0.02, 127.0.0.1:48040][0m
[mHTTP GET /api/schema/ 200 [0.05, 127.0.0.1:48040][0m
Internal Server Error: /users/register/
Traceback (most recent call last):
  File "/home/jahongir/Desktop/culinary/.venv/lib/python3.13/site-packages/kombu/utils/functional.py", line 32, in __call__
    return self.__value__
           ^^^^^^^^^^^^^^
AttributeError: 'ChannelPromise' object has no attribute '__value__'. Did you mean: '__call__'?

During handling of the above exception, another exception occurred:

Traceback (most recent call last):
  File "/home/jahongir/Desktop/culinary/.venv/lib/python3.13/site-packages/kombu/connection.py", line 472, in _reraise_as_library_errors
    yield
  File "/home/jahongir/Desktop/culinary/.venv/lib/python3.13/site-packages/kombu/connection.py", line 459, in _ensure_connection
    return retry_over_time(
        self._connection_factory, self.recoverable_connection_errors,
    ...<2 lines>...
        callback, timeout=timeout
    )
  File "/home/jahongir/Desktop/culinary/.venv/lib/python3.13/site-packages/kombu/utils/functional.py", line 318, in retry_over_time
    return fun(*args, **kwargs)
  File "/home/jahongir/Desktop/culinary/.venv/lib/python3.13/site-packages/kombu/connection.py", line 938, in _connection_factory
    self._connection = self._establish_connection()
                       ~~~~~~~~~~~~~~~~~~~~~~~~~~^^
  File "/home/jahongir/Desktop/culinary/.venv/lib/python3.13/site-packages/kombu/connection.py", line 860, in _establish_connection
    conn = self.transport.establish_connection()
  File "/home/jahongir/Desktop/culinary/.venv/lib/python3.13/site-packages/kombu/transport/pyamqp.py", line 203, in establish_connection
    conn.connect()
    ~~~~~~~~~~~~^^
  File "/home/jahongir/Desktop/culinary/.venv/lib/python3.13/site-packages/amqp/connection.py", line 324, in connect
    self.transport.connect()
    ~~~~~~~~~~~~~~~~~~~~~~^^
  File "/home/jahongir/Desktop/culinary/.venv/lib/python3.13/site-packages/amqp/transport.py", line 132, in connect
    self._connect(self.host, self.port, self.connect_timeout)
    ~~~~~~~~~~~~~^^^^^^^^^^^^^^^^^^^^^^^^^^^^^^^^^^^^^^^^^^^^
  File "/home/jahongir/Desktop/culinary/.venv/lib/python3.13/site-packages/amqp/transport.py", line 187, in _connect
    self.sock.connect(sa)
    ~~~~~~~~~~~~~~~~~^^^^
ConnectionRefusedError: [Errno 111] Connection refused

The above exception was the direct cause of the following exception:

Traceback (most recent call last):
  File "/home/jahongir/Desktop/culinary/.venv/lib/python3.13/site-packages/asgiref/sync.py", line 489, in thread_handler
    raise exc_info[1]
  File "/home/jahongir/Desktop/culinary/.venv/lib/python3.13/site-packages/django/core/handlers/exception.py", line 42, in inner
    response = await get_response(request)
               ^^^^^^^^^^^^^^^^^^^^^^^^^^^
  File "/home/jahongir/Desktop/culinary/.venv/lib/python3.13/site-packages/asgiref/sync.py", line 489, in thread_handler
    raise exc_info[1]
  File "/home/jahongir/Desktop/culinary/.venv/lib/python3.13/site-packages/django/core/handlers/base.py", line 253, in _get_response_async
    response = await wrapped_callback(
               ^^^^^^^^^^^^^^^^^^^^^^^
        request, *callback_args, **callback_kwargs
        ^^^^^^^^^^^^^^^^^^^^^^^^^^^^^^^^^^^^^^^^^^
    )
    ^
  File "/home/jahongir/Desktop/culinary/.venv/lib/python3.13/site-packages/asgiref/sync.py", line 439, in __call__
    ret = await asyncio.shield(exec_coro)
          ^^^^^^^^^^^^^^^^^^^^^^^^^^^^^^^
  File "/home/jahongir/.local/share/uv/python/cpython-3.13.5-linux-x86_64-gnu/lib/python3.13/concurrent/futures/thread.py", line 59, in run
    result = self.fn(*self.args, **self.kwargs)
  File "/home/jahongir/Desktop/culinary/.venv/lib/python3.13/site-packages/asgiref/sync.py", line 493, in thread_handler
    return func(*args, **kwargs)
  File "/home/jahongir/Desktop/culinary/.venv/lib/python3.13/site-packages/django/views/decorators/csrf.py", line 65, in _view_wrapper
    return view_func(request, *args, **kwargs)
  File "/home/jahongir/Desktop/culinary/.venv/lib/python3.13/site-packages/django/views/generic/base.py", line 105, in view
    return self.dispatch(request, *args, **kwargs)
           ~~~~~~~~~~~~~^^^^^^^^^^^^^^^^^^^^^^^^^^
  File "/home/jahongir/Desktop/culinary/.venv/lib/python3.13/site-packages/rest_framework/views.py", line 515, in dispatch
    response = self.handle_exception(exc)
  File "/home/jahongir/Desktop/culinary/.venv/lib/python3.13/site-packages/rest_framework/views.py", line 475, in handle_exception
    self.raise_uncaught_exception(exc)
    ~~~~~~~~~~~~~~~~~~~~~~~~~~~~~^^^^^
  File "/home/jahongir/Desktop/culinary/.venv/lib/python3.13/site-packages/rest_framework/views.py", line 486, in raise_uncaught_exception
    raise exc
  File "/home/jahongir/Desktop/culinary/.venv/lib/python3.13/site-packages/rest_framework/views.py", line 512, in dispatch
    response = handler(request, *args, **kwargs)
  File "/home/jahongir/Desktop/culinary/.venv/lib/python3.13/site-packages/rest_framework/generics.py", line 194, in post
    return self.create(request, *args, **kwargs)
           ~~~~~~~~~~~^^^^^^^^^^^^^^^^^^^^^^^^^^
  File "/home/jahongir/Desktop/culinary/.venv/lib/python3.13/site-packages/rest_framework/mixins.py", line 19, in create
    self.perform_create(serializer)
    ~~~~~~~~~~~~~~~~~~~^^^^^^^^^^^^
  File "/home/jahongir/Desktop/culinary/.venv/lib/python3.13/site-packages/rest_framework/mixins.py", line 24, in perform_create
    serializer.save()
    ~~~~~~~~~~~~~~~^^
  File "/home/jahongir/Desktop/culinary/users/serializers.py", line 24, in save
    send_register_email.delay(user_id=user.id, email=user.email)
    ~~~~~~~~~~~~~~~~~~~~~~~~~^^^^^^^^^^^^^^^^^^^^^^^^^^^^^^^^^^^
  File "/home/jahongir/Desktop/culinary/.venv/lib/python3.13/site-packages/celery/app/task.py", line 444, in delay
    return self.apply_async(args, kwargs)
           ~~~~~~~~~~~~~~~~^^^^^^^^^^^^^^
  File "/home/jahongir/Desktop/culinary/.venv/lib/python3.13/site-packages/celery/app/task.py", line 601, in apply_async
    return app.send_task(
           ~~~~~~~~~~~~~^
        self.name, args, kwargs, task_id=task_id, producer=producer,
        ^^^^^^^^^^^^^^^^^^^^^^^^^^^^^^^^^^^^^^^^^^^^^^^^^^^^^^^^^^^^
    ...<2 lines>...
        **options
        ^^^^^^^^^
    )
    ^
  File "/home/jahongir/Desktop/culinary/.venv/lib/python3.13/site-packages/celery/app/base.py", line 930, in send_task
    amqp.send_task_message(P, name, message, **options)
    ~~~~~~~~~~~~~~~~~~~~~~^^^^^^^^^^^^^^^^^^^^^^^^^^^^^
  File "/home/jahongir/Desktop/culinary/.venv/lib/python3.13/site-packages/celery/app/amqp.py", line 523, in send_task_message
    ret = producer.publish(
        body,
    ...<8 lines>...
        **properties
    )
  File "/home/jahongir/Desktop/culinary/.venv/lib/python3.13/site-packages/kombu/messaging.py", line 190, in publish
    return _publish(
        body, priority, content_type, content_encoding,
        headers, properties, routing_key, mandatory, immediate,
        exchange_name, declare, timeout, confirm_timeout, retry, retry_policy
    )
  File "/home/jahongir/Desktop/culinary/.venv/lib/python3.13/site-packages/kombu/connection.py", line 556, in _ensured
    return fun(*args, **kwargs)
  File "/home/jahongir/Desktop/culinary/.venv/lib/python3.13/site-packages/kombu/messaging.py", line 200, in _publish
    channel = self.channel
              ^^^^^^^^^^^^
  File "/home/jahongir/Desktop/culinary/.venv/lib/python3.13/site-packages/kombu/messaging.py", line 224, in _get_channel
    channel = self._channel = channel()
                              ~~~~~~~^^
  File "/home/jahongir/Desktop/culinary/.venv/lib/python3.13/site-packages/kombu/utils/functional.py", line 34, in __call__
    value = self.__value__ = self.__contract__()
                             ~~~~~~~~~~~~~~~~~^^
  File "/home/jahongir/Desktop/culinary/.venv/lib/python3.13/site-packages/kombu/messaging.py", line 240, in <lambda>
    channel = ChannelPromise(lambda: connection.default_channel)
                                     ^^^^^^^^^^^^^^^^^^^^^^^^^^
  File "/home/jahongir/Desktop/culinary/.venv/lib/python3.13/site-packages/kombu/connection.py", line 957, in default_channel
    self._ensure_connection(**conn_opts)
    ~~~~~~~~~~~~~~~~~~~~~~~^^^^^^^^^^^^^
  File "/home/jahongir/Desktop/culinary/.venv/lib/python3.13/site-packages/kombu/connection.py", line 458, in _ensure_connection
    with ctx():
         ~~~^^
  File "/home/jahongir/.local/share/uv/python/cpython-3.13.5-linux-x86_64-gnu/lib/python3.13/contextlib.py", line 162, in __exit__
    self.gen.throw(value)
    ~~~~~~~~~~~~~~^^^^^^^
  File "/home/jahongir/Desktop/culinary/.venv/lib/python3.13/site-packages/kombu/connection.py", line 476, in _reraise_as_library_errors
    raise ConnectionError(str(exc)) from exc
kombu.exceptions.OperationalError: [Errno 111] Connection refused
[35;1mHTTP POST /users/register/ 500 [1.09, 127.0.0.1:48040][0m
Internal Server Error: /users/register/
Traceback (most recent call last):
  File "/home/jahongir/Desktop/culinary/.venv/lib/python3.13/site-packages/kombu/utils/functional.py", line 32, in __call__
    return self.__value__
           ^^^^^^^^^^^^^^
AttributeError: 'ChannelPromise' object has no attribute '__value__'. Did you mean: '__call__'?

During handling of the above exception, another exception occurred:

Traceback (most recent call last):
  File "/home/jahongir/Desktop/culinary/.venv/lib/python3.13/site-packages/kombu/connection.py", line 472, in _reraise_as_library_errors
    yield
  File "/home/jahongir/Desktop/culinary/.venv/lib/python3.13/site-packages/kombu/connection.py", line 459, in _ensure_connection
    return retry_over_time(
        self._connection_factory, self.recoverable_connection_errors,
    ...<2 lines>...
        callback, timeout=timeout
    )
  File "/home/jahongir/Desktop/culinary/.venv/lib/python3.13/site-packages/kombu/utils/functional.py", line 318, in retry_over_time
    return fun(*args, **kwargs)
  File "/home/jahongir/Desktop/culinary/.venv/lib/python3.13/site-packages/kombu/connection.py", line 938, in _connection_factory
    self._connection = self._establish_connection()
                       ~~~~~~~~~~~~~~~~~~~~~~~~~~^^
  File "/home/jahongir/Desktop/culinary/.venv/lib/python3.13/site-packages/kombu/connection.py", line 860, in _establish_connection
    conn = self.transport.establish_connection()
  File "/home/jahongir/Desktop/culinary/.venv/lib/python3.13/site-packages/kombu/transport/pyamqp.py", line 203, in establish_connection
    conn.connect()
    ~~~~~~~~~~~~^^
  File "/home/jahongir/Desktop/culinary/.venv/lib/python3.13/site-packages/amqp/connection.py", line 324, in connect
    self.transport.connect()
    ~~~~~~~~~~~~~~~~~~~~~~^^
  File "/home/jahongir/Desktop/culinary/.venv/lib/python3.13/site-packages/amqp/transport.py", line 132, in connect
    self._connect(self.host, self.port, self.connect_timeout)
    ~~~~~~~~~~~~~^^^^^^^^^^^^^^^^^^^^^^^^^^^^^^^^^^^^^^^^^^^^
  File "/home/jahongir/Desktop/culinary/.venv/lib/python3.13/site-packages/amqp/transport.py", line 187, in _connect
    self.sock.connect(sa)
    ~~~~~~~~~~~~~~~~~^^^^
ConnectionRefusedError: [Errno 111] Connection refused

The above exception was the direct cause of the following exception:

Traceback (most recent call last):
  File "/home/jahongir/Desktop/culinary/.venv/lib/python3.13/site-packages/asgiref/sync.py", line 489, in thread_handler
    raise exc_info[1]
  File "/home/jahongir/Desktop/culinary/.venv/lib/python3.13/site-packages/django/core/handlers/exception.py", line 42, in inner
    response = await get_response(request)
               ^^^^^^^^^^^^^^^^^^^^^^^^^^^
  File "/home/jahongir/Desktop/culinary/.venv/lib/python3.13/site-packages/asgiref/sync.py", line 489, in thread_handler
    raise exc_info[1]
  File "/home/jahongir/Desktop/culinary/.venv/lib/python3.13/site-packages/django/core/handlers/base.py", line 253, in _get_response_async
    response = await wrapped_callback(
               ^^^^^^^^^^^^^^^^^^^^^^^
        request, *callback_args, **callback_kwargs
        ^^^^^^^^^^^^^^^^^^^^^^^^^^^^^^^^^^^^^^^^^^
    )
    ^
  File "/home/jahongir/Desktop/culinary/.venv/lib/python3.13/site-packages/asgiref/sync.py", line 439, in __call__
    ret = await asyncio.shield(exec_coro)
          ^^^^^^^^^^^^^^^^^^^^^^^^^^^^^^^
  File "/home/jahongir/.local/share/uv/python/cpython-3.13.5-linux-x86_64-gnu/lib/python3.13/concurrent/futures/thread.py", line 59, in run
    result = self.fn(*self.args, **self.kwargs)
  File "/home/jahongir/Desktop/culinary/.venv/lib/python3.13/site-packages/asgiref/sync.py", line 493, in thread_handler
    return func(*args, **kwargs)
  File "/home/jahongir/Desktop/culinary/.venv/lib/python3.13/site-packages/django/views/decorators/csrf.py", line 65, in _view_wrapper
    return view_func(request, *args, **kwargs)
  File "/home/jahongir/Desktop/culinary/.venv/lib/python3.13/site-packages/django/views/generic/base.py", line 105, in view
    return self.dispatch(request, *args, **kwargs)
           ~~~~~~~~~~~~~^^^^^^^^^^^^^^^^^^^^^^^^^^
  File "/home/jahongir/Desktop/culinary/.venv/lib/python3.13/site-packages/rest_framework/views.py", line 515, in dispatch
    response = self.handle_exception(exc)
  File "/home/jahongir/Desktop/culinary/.venv/lib/python3.13/site-packages/rest_framework/views.py", line 475, in handle_exception
    self.raise_uncaught_exception(exc)
    ~~~~~~~~~~~~~~~~~~~~~~~~~~~~~^^^^^
  File "/home/jahongir/Desktop/culinary/.venv/lib/python3.13/site-packages/rest_framework/views.py", line 486, in raise_uncaught_exception
    raise exc
  File "/home/jahongir/Desktop/culinary/.venv/lib/python3.13/site-packages/rest_framework/views.py", line 512, in dispatch
    response = handler(request, *args, **kwargs)
  File "/home/jahongir/Desktop/culinary/.venv/lib/python3.13/site-packages/rest_framework/generics.py", line 194, in post
    return self.create(request, *args, **kwargs)
           ~~~~~~~~~~~^^^^^^^^^^^^^^^^^^^^^^^^^^
  File "/home/jahongir/Desktop/culinary/.venv/lib/python3.13/site-packages/rest_framework/mixins.py", line 19, in create
    self.perform_create(serializer)
    ~~~~~~~~~~~~~~~~~~~^^^^^^^^^^^^
  File "/home/jahongir/Desktop/culinary/.venv/lib/python3.13/site-packages/rest_framework/mixins.py", line 24, in perform_create
    serializer.save()
    ~~~~~~~~~~~~~~~^^
  File "/home/jahongir/Desktop/culinary/users/serializers.py", line 24, in save
    send_register_email.delay(user_id=user.id, email=user.email)
    ~~~~~~~~~~~~~~~~~~~~~~~~~^^^^^^^^^^^^^^^^^^^^^^^^^^^^^^^^^^^
  File "/home/jahongir/Desktop/culinary/.venv/lib/python3.13/site-packages/celery/app/task.py", line 444, in delay
    return self.apply_async(args, kwargs)
           ~~~~~~~~~~~~~~~~^^^^^^^^^^^^^^
  File "/home/jahongir/Desktop/culinary/.venv/lib/python3.13/site-packages/celery/app/task.py", line 601, in apply_async
    return app.send_task(
           ~~~~~~~~~~~~~^
        self.name, args, kwargs, task_id=task_id, producer=producer,
        ^^^^^^^^^^^^^^^^^^^^^^^^^^^^^^^^^^^^^^^^^^^^^^^^^^^^^^^^^^^^
    ...<2 lines>...
        **options
        ^^^^^^^^^
    )
    ^
  File "/home/jahongir/Desktop/culinary/.venv/lib/python3.13/site-packages/celery/app/base.py", line 930, in send_task
    amqp.send_task_message(P, name, message, **options)
    ~~~~~~~~~~~~~~~~~~~~~~^^^^^^^^^^^^^^^^^^^^^^^^^^^^^
  File "/home/jahongir/Desktop/culinary/.venv/lib/python3.13/site-packages/celery/app/amqp.py", line 523, in send_task_message
    ret = producer.publish(
        body,
    ...<8 lines>...
        **properties
    )
  File "/home/jahongir/Desktop/culinary/.venv/lib/python3.13/site-packages/kombu/messaging.py", line 190, in publish
    return _publish(
        body, priority, content_type, content_encoding,
        headers, properties, routing_key, mandatory, immediate,
        exchange_name, declare, timeout, confirm_timeout, retry, retry_policy
    )
  File "/home/jahongir/Desktop/culinary/.venv/lib/python3.13/site-packages/kombu/connection.py", line 556, in _ensured
    return fun(*args, **kwargs)
  File "/home/jahongir/Desktop/culinary/.venv/lib/python3.13/site-packages/kombu/messaging.py", line 200, in _publish
    channel = self.channel
              ^^^^^^^^^^^^
  File "/home/jahongir/Desktop/culinary/.venv/lib/python3.13/site-packages/kombu/messaging.py", line 224, in _get_channel
    channel = self._channel = channel()
                              ~~~~~~~^^
  File "/home/jahongir/Desktop/culinary/.venv/lib/python3.13/site-packages/kombu/utils/functional.py", line 34, in __call__
    value = self.__value__ = self.__contract__()
                             ~~~~~~~~~~~~~~~~~^^
  File "/home/jahongir/Desktop/culinary/.venv/lib/python3.13/site-packages/kombu/messaging.py", line 240, in <lambda>
    channel = ChannelPromise(lambda: connection.default_channel)
                                     ^^^^^^^^^^^^^^^^^^^^^^^^^^
  File "/home/jahongir/Desktop/culinary/.venv/lib/python3.13/site-packages/kombu/connection.py", line 957, in default_channel
    self._ensure_connection(**conn_opts)
    ~~~~~~~~~~~~~~~~~~~~~~~^^^^^^^^^^^^^
  File "/home/jahongir/Desktop/culinary/.venv/lib/python3.13/site-packages/kombu/connection.py", line 458, in _ensure_connection
    with ctx():
         ~~~^^
  File "/home/jahongir/.local/share/uv/python/cpython-3.13.5-linux-x86_64-gnu/lib/python3.13/contextlib.py", line 162, in __exit__
    self.gen.throw(value)
    ~~~~~~~~~~~~~~^^^^^^^
  File "/home/jahongir/Desktop/culinary/.venv/lib/python3.13/site-packages/kombu/connection.py", line 476, in _reraise_as_library_errors
    raise ConnectionError(str(exc)) from exc
kombu.exceptions.OperationalError: [Errno 111] Connection refused
[35;1mHTTP POST /users/register/ 500 [1.01, 127.0.0.1:48040][0m
/home/jahongir/Desktop/culinary/core/__init__.py changed, reloading.
Watching for file changes with StatReloader
Internal Server Error: /users/register/
Traceback (most recent call last):
  File "/home/jahongir/Desktop/culinary/.venv/lib/python3.13/site-packages/django/db/backends/utils.py", line 105, in _execute
    return self.cursor.execute(sql, params)
           ~~~~~~~~~~~~~~~~~~~^^^^^^^^^^^^^
psycopg2.errors.UniqueViolation: duplicate key value violates unique constraint "users_user_email_key"
DETAIL:  Key (email)=(bex@gmail.com) already exists.


The above exception was the direct cause of the following exception:

Traceback (most recent call last):
  File "/home/jahongir/Desktop/culinary/.venv/lib/python3.13/site-packages/asgiref/sync.py", line 489, in thread_handler
    raise exc_info[1]
  File "/home/jahongir/Desktop/culinary/.venv/lib/python3.13/site-packages/django/core/handlers/exception.py", line 42, in inner
    response = await get_response(request)
               ^^^^^^^^^^^^^^^^^^^^^^^^^^^
  File "/home/jahongir/Desktop/culinary/.venv/lib/python3.13/site-packages/asgiref/sync.py", line 489, in thread_handler
    raise exc_info[1]
  File "/home/jahongir/Desktop/culinary/.venv/lib/python3.13/site-packages/django/core/handlers/base.py", line 253, in _get_response_async
    response = await wrapped_callback(
               ^^^^^^^^^^^^^^^^^^^^^^^
        request, *callback_args, **callback_kwargs
        ^^^^^^^^^^^^^^^^^^^^^^^^^^^^^^^^^^^^^^^^^^
    )
    ^
  File "/home/jahongir/Desktop/culinary/.venv/lib/python3.13/site-packages/asgiref/sync.py", line 439, in __call__
    ret = await asyncio.shield(exec_coro)
          ^^^^^^^^^^^^^^^^^^^^^^^^^^^^^^^
  File "/home/jahongir/.local/share/uv/python/cpython-3.13.5-linux-x86_64-gnu/lib/python3.13/concurrent/futures/thread.py", line 59, in run
    result = self.fn(*self.args, **self.kwargs)
  File "/home/jahongir/Desktop/culinary/.venv/lib/python3.13/site-packages/asgiref/sync.py", line 493, in thread_handler
    return func(*args, **kwargs)
  File "/home/jahongir/Desktop/culinary/.venv/lib/python3.13/site-packages/django/views/decorators/csrf.py", line 65, in _view_wrapper
    return view_func(request, *args, **kwargs)
  File "/home/jahongir/Desktop/culinary/.venv/lib/python3.13/site-packages/django/views/generic/base.py", line 105, in view
    return self.dispatch(request, *args, **kwargs)
           ~~~~~~~~~~~~~^^^^^^^^^^^^^^^^^^^^^^^^^^
  File "/home/jahongir/Desktop/culinary/.venv/lib/python3.13/site-packages/rest_framework/views.py", line 515, in dispatch
    response = self.handle_exception(exc)
  File "/home/jahongir/Desktop/culinary/.venv/lib/python3.13/site-packages/rest_framework/views.py", line 475, in handle_exception
    self.raise_uncaught_exception(exc)
    ~~~~~~~~~~~~~~~~~~~~~~~~~~~~~^^^^^
  File "/home/jahongir/Desktop/culinary/.venv/lib/python3.13/site-packages/rest_framework/views.py", line 486, in raise_uncaught_exception
    raise exc
  File "/home/jahongir/Desktop/culinary/.venv/lib/python3.13/site-packages/rest_framework/views.py", line 512, in dispatch
    response = handler(request, *args, **kwargs)
  File "/home/jahongir/Desktop/culinary/.venv/lib/python3.13/site-packages/rest_framework/generics.py", line 194, in post
    return self.create(request, *args, **kwargs)
           ~~~~~~~~~~~^^^^^^^^^^^^^^^^^^^^^^^^^^
  File "/home/jahongir/Desktop/culinary/.venv/lib/python3.13/site-packages/rest_framework/mixins.py", line 19, in create
    self.perform_create(serializer)
    ~~~~~~~~~~~~~~~~~~~^^^^^^^^^^^^
  File "/home/jahongir/Desktop/culinary/.venv/lib/python3.13/site-packages/rest_framework/mixins.py", line 24, in perform_create
    serializer.save()
    ~~~~~~~~~~~~~~~^^
  File "/home/jahongir/Desktop/culinary/users/serializers.py", line 20, in save
    user = User.objects._create_user(email=self.validated_data["email"],
    password=self.validated_data["password"],
    is_confirmed=False,)
  File "/home/jahongir/Desktop/culinary/users/manager.py", line 9, in _create_user
    user.save(using=self.db)
    ~~~~~~~~~^^^^^^^^^^^^^^^
  File "/home/jahongir/Desktop/culinary/.venv/lib/python3.13/site-packages/django/contrib/auth/base_user.py", line 65, in save
    super().save(*args, **kwargs)
    ~~~~~~~~~~~~^^^^^^^^^^^^^^^^^
  File "/home/jahongir/Desktop/culinary/.venv/lib/python3.13/site-packages/django/db/models/base.py", line 902, in save
    self.save_base(
    ~~~~~~~~~~~~~~^
        using=using,
        ^^^^^^^^^^^^
    ...<2 lines>...
        update_fields=update_fields,
        ^^^^^^^^^^^^^^^^^^^^^^^^^^^^
    )
    ^
  File "/home/jahongir/Desktop/culinary/.venv/lib/python3.13/site-packages/django/db/models/base.py", line 1008, in save_base
    updated = self._save_table(
        raw,
    ...<4 lines>...
        update_fields,
    )
  File "/home/jahongir/Desktop/culinary/.venv/lib/python3.13/site-packages/django/db/models/base.py", line 1169, in _save_table
    results = self._do_insert(
        cls._base_manager, using, fields, returning_fields, raw
    )
  File "/home/jahongir/Desktop/culinary/.venv/lib/python3.13/site-packages/django/db/models/base.py", line 1210, in _do_insert
    return manager._insert(
           ~~~~~~~~~~~~~~~^
        [self],
        ^^^^^^^
    ...<3 lines>...
        raw=raw,
        ^^^^^^^^
    )
    ^
  File "/home/jahongir/Desktop/culinary/.venv/lib/python3.13/site-packages/django/db/models/manager.py", line 87, in manager_method
    return getattr(self.get_queryset(), name)(*args, **kwargs)
           ~~~~~~~~~~~~~~~~~~~~~~~~~~~~~~~~~~^^^^^^^^^^^^^^^^^
  File "/home/jahongir/Desktop/culinary/.venv/lib/python3.13/site-packages/django/db/models/query.py", line 1868, in _insert
    return query.get_compiler(using=using).execute_sql(returning_fields)
           ~~~~~~~~~~~~~~~~~~~~~~~~~~~~~~~~~~~~~~~~~~~^^^^^^^^^^^^^^^^^^
  File "/home/jahongir/Desktop/culinary/.venv/lib/python3.13/site-packages/django/db/models/sql/compiler.py", line 1882, in execute_sql
    cursor.execute(sql, params)
    ~~~~~~~~~~~~~~^^^^^^^^^^^^^
  File "/home/jahongir/Desktop/culinary/.venv/lib/python3.13/site-packages/django/db/backends/utils.py", line 122, in execute
    return super().execute(sql, params)
           ~~~~~~~~~~~~~~~^^^^^^^^^^^^^
  File "/home/jahongir/Desktop/culinary/.venv/lib/python3.13/site-packages/django/db/backends/utils.py", line 79, in execute
    return self._execute_with_wrappers(
           ~~~~~~~~~~~~~~~~~~~~~~~~~~~^
        sql, params, many=False, executor=self._execute
        ^^^^^^^^^^^^^^^^^^^^^^^^^^^^^^^^^^^^^^^^^^^^^^^
    )
    ^
  File "/home/jahongir/Desktop/culinary/.venv/lib/python3.13/site-packages/django/db/backends/utils.py", line 92, in _execute_with_wrappers
    return executor(sql, params, many, context)
  File "/home/jahongir/Desktop/culinary/.venv/lib/python3.13/site-packages/django/db/backends/utils.py", line 100, in _execute
    with self.db.wrap_database_errors:
         ^^^^^^^^^^^^^^^^^^^^^^^^^^^^
  File "/home/jahongir/Desktop/culinary/.venv/lib/python3.13/site-packages/django/db/utils.py", line 91, in __exit__
    raise dj_exc_value.with_traceback(traceback) from exc_value
  File "/home/jahongir/Desktop/culinary/.venv/lib/python3.13/site-packages/django/db/backends/utils.py", line 105, in _execute
    return self.cursor.execute(sql, params)
           ~~~~~~~~~~~~~~~~~~~^^^^^^^^^^^^^
django.db.utils.IntegrityError: duplicate key value violates unique constraint "users_user_email_key"
DETAIL:  Key (email)=(bex@gmail.com) already exists.

[35;1mHTTP POST /users/register/ 500 [0.48, 127.0.0.1:51594][0m
Internal Server Error: /users/register/
Traceback (most recent call last):
  File "/home/jahongir/Desktop/culinary/.venv/lib/python3.13/site-packages/django/db/backends/utils.py", line 105, in _execute
    return self.cursor.execute(sql, params)
           ~~~~~~~~~~~~~~~~~~~^^^^^^^^^^^^^
psycopg2.errors.UniqueViolation: duplicate key value violates unique constraint "users_user_email_key"
DETAIL:  Key (email)=(bexruz@gmail.com) already exists.


The above exception was the direct cause of the following exception:

Traceback (most recent call last):
  File "/home/jahongir/Desktop/culinary/.venv/lib/python3.13/site-packages/asgiref/sync.py", line 489, in thread_handler
    raise exc_info[1]
  File "/home/jahongir/Desktop/culinary/.venv/lib/python3.13/site-packages/django/core/handlers/exception.py", line 42, in inner
    response = await get_response(request)
               ^^^^^^^^^^^^^^^^^^^^^^^^^^^
  File "/home/jahongir/Desktop/culinary/.venv/lib/python3.13/site-packages/asgiref/sync.py", line 489, in thread_handler
    raise exc_info[1]
  File "/home/jahongir/Desktop/culinary/.venv/lib/python3.13/site-packages/django/core/handlers/base.py", line 253, in _get_response_async
    response = await wrapped_callback(
               ^^^^^^^^^^^^^^^^^^^^^^^
        request, *callback_args, **callback_kwargs
        ^^^^^^^^^^^^^^^^^^^^^^^^^^^^^^^^^^^^^^^^^^
    )
    ^
  File "/home/jahongir/Desktop/culinary/.venv/lib/python3.13/site-packages/asgiref/sync.py", line 439, in __call__
    ret = await asyncio.shield(exec_coro)
          ^^^^^^^^^^^^^^^^^^^^^^^^^^^^^^^
  File "/home/jahongir/.local/share/uv/python/cpython-3.13.5-linux-x86_64-gnu/lib/python3.13/concurrent/futures/thread.py", line 59, in run
    result = self.fn(*self.args, **self.kwargs)
  File "/home/jahongir/Desktop/culinary/.venv/lib/python3.13/site-packages/asgiref/sync.py", line 493, in thread_handler
    return func(*args, **kwargs)
  File "/home/jahongir/Desktop/culinary/.venv/lib/python3.13/site-packages/django/views/decorators/csrf.py", line 65, in _view_wrapper
    return view_func(request, *args, **kwargs)
  File "/home/jahongir/Desktop/culinary/.venv/lib/python3.13/site-packages/django/views/generic/base.py", line 105, in view
    return self.dispatch(request, *args, **kwargs)
           ~~~~~~~~~~~~~^^^^^^^^^^^^^^^^^^^^^^^^^^
  File "/home/jahongir/Desktop/culinary/.venv/lib/python3.13/site-packages/rest_framework/views.py", line 515, in dispatch
    response = self.handle_exception(exc)
  File "/home/jahongir/Desktop/culinary/.venv/lib/python3.13/site-packages/rest_framework/views.py", line 475, in handle_exception
    self.raise_uncaught_exception(exc)
    ~~~~~~~~~~~~~~~~~~~~~~~~~~~~~^^^^^
  File "/home/jahongir/Desktop/culinary/.venv/lib/python3.13/site-packages/rest_framework/views.py", line 486, in raise_uncaught_exception
    raise exc
  File "/home/jahongir/Desktop/culinary/.venv/lib/python3.13/site-packages/rest_framework/views.py", line 512, in dispatch
    response = handler(request, *args, **kwargs)
  File "/home/jahongir/Desktop/culinary/.venv/lib/python3.13/site-packages/rest_framework/generics.py", line 194, in post
    return self.create(request, *args, **kwargs)
           ~~~~~~~~~~~^^^^^^^^^^^^^^^^^^^^^^^^^^
  File "/home/jahongir/Desktop/culinary/.venv/lib/python3.13/site-packages/rest_framework/mixins.py", line 19, in create
    self.perform_create(serializer)
    ~~~~~~~~~~~~~~~~~~~^^^^^^^^^^^^
  File "/home/jahongir/Desktop/culinary/.venv/lib/python3.13/site-packages/rest_framework/mixins.py", line 24, in perform_create
    serializer.save()
    ~~~~~~~~~~~~~~~^^
  File "/home/jahongir/Desktop/culinary/users/serializers.py", line 20, in save
    user = User.objects._create_user(email=self.validated_data["email"],
    password=self.validated_data["password"],
    is_confirmed=False,)
  File "/home/jahongir/Desktop/culinary/users/manager.py", line 9, in _create_user
    user.save(using=self.db)
    ~~~~~~~~~^^^^^^^^^^^^^^^
  File "/home/jahongir/Desktop/culinary/.venv/lib/python3.13/site-packages/django/contrib/auth/base_user.py", line 65, in save
    super().save(*args, **kwargs)
    ~~~~~~~~~~~~^^^^^^^^^^^^^^^^^
  File "/home/jahongir/Desktop/culinary/.venv/lib/python3.13/site-packages/django/db/models/base.py", line 902, in save
    self.save_base(
    ~~~~~~~~~~~~~~^
        using=using,
        ^^^^^^^^^^^^
    ...<2 lines>...
        update_fields=update_fields,
        ^^^^^^^^^^^^^^^^^^^^^^^^^^^^
    )
    ^
  File "/home/jahongir/Desktop/culinary/.venv/lib/python3.13/site-packages/django/db/models/base.py", line 1008, in save_base
    updated = self._save_table(
        raw,
    ...<4 lines>...
        update_fields,
    )
  File "/home/jahongir/Desktop/culinary/.venv/lib/python3.13/site-packages/django/db/models/base.py", line 1169, in _save_table
    results = self._do_insert(
        cls._base_manager, using, fields, returning_fields, raw
    )
  File "/home/jahongir/Desktop/culinary/.venv/lib/python3.13/site-packages/django/db/models/base.py", line 1210, in _do_insert
    return manager._insert(
           ~~~~~~~~~~~~~~~^
        [self],
        ^^^^^^^
    ...<3 lines>...
        raw=raw,
        ^^^^^^^^
    )
    ^
  File "/home/jahongir/Desktop/culinary/.venv/lib/python3.13/site-packages/django/db/models/manager.py", line 87, in manager_method
    return getattr(self.get_queryset(), name)(*args, **kwargs)
           ~~~~~~~~~~~~~~~~~~~~~~~~~~~~~~~~~~^^^^^^^^^^^^^^^^^
  File "/home/jahongir/Desktop/culinary/.venv/lib/python3.13/site-packages/django/db/models/query.py", line 1868, in _insert
    return query.get_compiler(using=using).execute_sql(returning_fields)
           ~~~~~~~~~~~~~~~~~~~~~~~~~~~~~~~~~~~~~~~~~~~^^^^^^^^^^^^^^^^^^
  File "/home/jahongir/Desktop/culinary/.venv/lib/python3.13/site-packages/django/db/models/sql/compiler.py", line 1882, in execute_sql
    cursor.execute(sql, params)
    ~~~~~~~~~~~~~~^^^^^^^^^^^^^
  File "/home/jahongir/Desktop/culinary/.venv/lib/python3.13/site-packages/django/db/backends/utils.py", line 122, in execute
    return super().execute(sql, params)
           ~~~~~~~~~~~~~~~^^^^^^^^^^^^^
  File "/home/jahongir/Desktop/culinary/.venv/lib/python3.13/site-packages/django/db/backends/utils.py", line 79, in execute
    return self._execute_with_wrappers(
           ~~~~~~~~~~~~~~~~~~~~~~~~~~~^
        sql, params, many=False, executor=self._execute
        ^^^^^^^^^^^^^^^^^^^^^^^^^^^^^^^^^^^^^^^^^^^^^^^
    )
    ^
  File "/home/jahongir/Desktop/culinary/.venv/lib/python3.13/site-packages/django/db/backends/utils.py", line 92, in _execute_with_wrappers
    return executor(sql, params, many, context)
  File "/home/jahongir/Desktop/culinary/.venv/lib/python3.13/site-packages/django/db/backends/utils.py", line 100, in _execute
    with self.db.wrap_database_errors:
         ^^^^^^^^^^^^^^^^^^^^^^^^^^^^
  File "/home/jahongir/Desktop/culinary/.venv/lib/python3.13/site-packages/django/db/utils.py", line 91, in __exit__
    raise dj_exc_value.with_traceback(traceback) from exc_value
  File "/home/jahongir/Desktop/culinary/.venv/lib/python3.13/site-packages/django/db/backends/utils.py", line 105, in _execute
    return self.cursor.execute(sql, params)
           ~~~~~~~~~~~~~~~~~~~^^^^^^^^^^^^^
django.db.utils.IntegrityError: duplicate key value violates unique constraint "users_user_email_key"
DETAIL:  Key (email)=(bexruz@gmail.com) already exists.

[35;1mHTTP POST /users/register/ 500 [0.42, 127.0.0.1:51594][0m
Unauthorized: /recipes/categories/create/
[31;1mHTTP POST /recipes/categories/create/ 401 [0.02, 127.0.0.1:60322][0m
[mHTTP GET /recipes/categories/ 200 [0.02, 127.0.0.1:60322][0m
Unauthorized: /recipes/categories/1/delete/
[31;1mHTTP DELETE /recipes/categories/1/delete/ 401 [0.01, 127.0.0.1:60322][0m
